MySQL connections errors

File "server.py", line 7, in <module>
    mysql = MySQLConnector(app, 'mydb')
  File "C:\Users\Evan\Desktop\DojoAssignments\PythonAssignments\flask_MySQL\flask_mysql\test_connection\mysqlconnection.py", line 40, in MySQLConnector
    return MySQLConnection(app, db)
  File "C:\Users\Evan\Desktop\DojoAssignments\PythonAssignments\flask_MySQL\flask_mysql\test_connection\mysqlconnection.py", line 9, in __init__
    'database': d, # we got db as an argument
NameError: global name 'd' is not defined

Changed the database: 'db' to database: 'd' and got the above error

----------------------------------

sqlalchemy.exc.OperationalError: (_mysql_exceptions.OperationalError) 
(1045, "Access denied for user 'root'@'localhost' (using password: YES)")

Changed the localhost password to 'boot' instead of 'root' and got the above error

----------------------------------

sqlalchemy.exc.OperationalError: (_mysql_exceptions.OperationalError) 
(1045, "Access denied for user 'rot'@'localhost' (using password: YES)")

Changes the localhost name to rot and the above error showed up

----------------------------------




